<?xml version="1.0" ?>
<!-- =================================================================================== -->
<!-- |    This document was autogenerated by xacro from rrbot.xacro                    | -->
<!-- |    EDITING THIS FILE BY HAND IS NOT RECOMMENDED                                 | -->
<!-- =================================================================================== -->
<!-- Revolute-Revolute Manipulator -->
<robot name="rrbot">
  <!-- ros_control plugin -->
  <gazebo>
    <plugin filename="libgazebo_ros_control.so" name="gazebo_ros_control">
      <robotNamespace>/rrbot</robotNamespace>
      <robotSimType>gazebo_ros_control/DefaultRobotHWSim</robotSimType>
    </plugin>
    <plugin filename="libgazebo_ros_p3d.so" name="rrbot_groundtruth">
      <robotNamespace>/rrbot</robotNamespace>
      <frameName>world</frameName>
      <alwaysOn>true</alwaysOn>
      <bodyName>FC</bodyName>
      <topicName>position_groundtruth</topicName>
      <gaussianNoise>0.00</gaussianNoise>
      <updateRate>100.0</updateRate>
    </plugin>
    <plugin filename="libhector_gazebo_ros_imu.so" name="quadrotor_imu_gt">
      <robotNamespace>/rrbot</robotNamespace>
      <updateRate>100.0</updateRate>
      <frameId>world</frameId>
      <bodyName>FC</bodyName>
      <topicName>imu_groundtruth</topicName>
      <rpyOffset>0 0 0</rpyOffset>
      <!-- deprecated -->
      <gaussianNoise>0</gaussianNoise>
      <!-- deprecated -->
      <accelDrift>0 0 0</accelDrift>
      <accelGaussianNoise>0 0 0</accelGaussianNoise>
      <rateDrift>0 0 0</rateDrift>
      <rateGaussianNoise>0 0 0</rateGaussianNoise>
    </plugin>
    <plugin filename="libhector_gazebo_ros_imu.so" name="quadrotor_imu_sim">
      <robotNamespace>/rrbot</robotNamespace>
      <updateRate>100.0</updateRate>
      <frameId>world</frameId>
      <bodyName>FC</bodyName>
      <topicName>sim_imu</topicName>
      <rpyOffset>0 0 0</rpyOffset>
      <!-- deprecated -->
      <gaussianNoise>0</gaussianNoise>
      <!-- deprecated -->
      <accelDrift>0.05 0.05 0.05</accelDrift>
      <accelGaussianNoise>0.35 0.35 0.3</accelGaussianNoise>
      <rateDrift>0.1 0.1 0.1</rateDrift>
      <rateGaussianNoise>0.05 0.05 0.015</rateGaussianNoise>
    </plugin>
    <plugin filename="libhector_gazebo_ros_baro.so" name="quadrotor_baro_sim">
      <robotNamespace>/rrbot</robotNamespace>
      <updateRate>10.0</updateRate>
      <bodyName>FC</bodyName>
      <frameId>world</frameId>
      <topicName>sim_barometer</topicName>
      <altimeterTopicName>sim_altimeter</altimeterTopicName>
      <offset>0</offset>
      <drift>10.0</drift>
      <gaussianNoise>0.1</gaussianNoise>
    </plugin>
    <plugin filename="libhector_gazebo_ros_magnetic.so" name="quadrotor_magnetic_sim">
      <robotNamespace>/rrbot</robotNamespace>
      <updateRate>10.0</updateRate>
      <bodyName>FC</bodyName>
      <frameId>world</frameId>
      <topicName>sim_magnetometer</topicName>
      <offset>0 0 0</offset>
      <drift>0.0 0.0 0.0</drift>
      <gaussianNoise>1.3e-2 1.3e-2 1.3e-2</gaussianNoise>
    </plugin>
    <plugin filename="libhector_gazebo_ros_gps.so" name="quadrotor_gps_sim">
      <robotNamespace>/rrbot</robotNamespace>
      <updateRate>5.0</updateRate>
      <bodyName>FC</bodyName>
      <frameId>world</frameId>
      <topicName>sim_gps_fix</topicName>
      <velocityTopicName>sim_gps_vel</velocityTopicName>
      <referenceLatitude>48.75</referenceLatitude>
      <referenceLongitude>9.105</referenceLongitude>
      <drift>5.0 5.0 5.0</drift>
      <gaussianNoise>0.01 0.01 0.01</gaussianNoise>
      <velocityDrift>0 0 0</velocityDrift>
      <velocityGaussianNoise>0.05 0.05 0.05</velocityGaussianNoise>
    </plugin>
  </gazebo>
  <!-- The ft_sensor plugin 
    <gazebo reference="$FC_joint">
      <provideFeedback>true</provideFeedback>
    </gazebo>

	
    <gazebo>
      <plugin name="ft_sensor" filename="libgazebo_ros_ft_sensor.so">
        <updateRate>100.0</updateRate>
        <topicName>force_torque</topicName>
        <jointName>FC_joint</jointName>
     </plugin>
   </gazebo>
    
     The ft_sensor plugin -->
  <material name="Black">
    <color rgba="0.0 0.0 0.0 1.0"/>
  </material>
  <material name="Blue">
    <color rgba="0.0 0.0 0.8 1.0"/>
  </material>
  <material name="Green">
    <color rgba="0.0 0.8 0.0 1.0"/>
  </material>
  <material name="Grey">
    <color rgba="0.2 0.2 0.2 1.0"/>
  </material>
  <material name="Orange">
    <color rgba="1.0 0.4235294117647059 0.0392156862745098 1.0"/>
  </material>
  <material name="Brown">
    <color rgba="0.8705882352941177 0.8117647058823529 0.7647058823529411 1.0"/>
  </material>
  <material name="Red">
    <color rgba="0.8 0.0 0.0 1.0"/>
  </material>
  <material name="White">
    <color rgba="1.0 1.0 1.0 1.0"/>
  </material>
  <!-- dummy root link used for a vehicle that is not glued to the world map-->
  <link name="dummyroot"/>
  <link name="FC">
    <collision>
      <origin rpy="0 0 0" xyz="0 0 0"/>
      <geometry>
        <box size="0.05 0.05 0.005"/>
      </geometry>
    </collision>
    <visual>
      <origin rpy="0 0 0" xyz="0 0 0"/>
      <geometry>
        <box size="0.05 0.05 0.005"/>
      </geometry>
      <material name="Black"/>
    </visual>
    <inertial>
      <origin rpy="0 0 0" xyz="0 0 0"/>
      <mass value="0.002"/>
      <inertia ixx="4.2083333333333336e-07" ixy="0.0" ixz="0.0" iyy="4.2083333333333336e-07" iyz="0.0" izz="8.333333333333334e-07"/>
    </inertial>
  </link>
  <gazebo reference="FC">
    <material>Gazebo/Black</material>
    <mu1>0.2</mu1>
    <mu2>0.2</mu2>
  </gazebo>
  <joint name="FC_joint" type="revolute">
    <parent link="dummyroot"/>
    <origin rpy="0 0 0" xyz="0 0 0.01"/>
    <child link="FC"/>
    <limit effort="1000" lower="0" upper="0" velocity="10"/>
  </joint>
  <link name="FT_sensor">
    <collision>
      <origin rpy="0 0 0" xyz="0 0 0"/>
      <geometry>
        <box size="0.005 0.0005 0.0005"/>
      </geometry>
    </collision>
    <visual>
      <origin rpy="0 0 0" xyz="0 0 0"/>
      <geometry>
        <box size="0.005 0.0005 0.0005"/>
      </geometry>
      <material name="Black"/>
    </visual>
    <inertial>
      <origin rpy="0 0 0" xyz="0 0 0"/>
      <mass value="1e-05"/>
      <inertia ixx="4.166666666666667e-13" ixy="0.0" ixz="0.0" iyy="2.1041666666666668e-11" iyz="0.0" izz="2.1041666666666668e-11"/>
    </inertial>
  </link>
  <gazebo reference="FT_sensor">
    <material>Gazebo/Black</material>
    <mu1>0.2</mu1>
    <mu2>0.2</mu2>
  </gazebo>
  <joint name="FT_sensor_joint" type="revolute">
    <parent link="bar0"/>
    <origin rpy="0 0 0" xyz="0 0 0.00"/>
    <child link="FT_sensor"/>
    <limit effort="1000" lower="0" upper="0" velocity="10"/>
  </joint>
  <!-- <xacro:box_base_link name="FT_sensor" m="0.001" x="0.005" y="0.005" z="0.005" mat="Black">
        <nothing/>
    </xacro:box_base_link> -->
  <!-- <joint name="FT_sensor_joint" type="revolute">
        <parent link="dummyroot_FT"/>
        <origin xyz="0 0 0.01" rpy="0 0  ${PI/4}"/>
        <child link="FT_sensor"/>
        <limit effort="1000" velocity="10" lower="0" upper="0" />
    </joint> -->
  <!-- <joint name="${name}" type="revolute">
   <parent link="${parent}"/>
   <child link="${child}"/>
   <origin rpy="0 0 0" xyz="0 0 0"/>
   <axis xyz="1 0 0"/>
   <limit effort="1000" lower="0" upper="0" velocity="10"/>
  </joint>  -->
  <gazebo reference="FT_sensor_joint">
    <provideFeedback>true</provideFeedback>
  </gazebo>
  <!-- The ft_sensor plugin -->
  <gazebo>
    <plugin filename="libgazebo_ros_ft_sensor.so" name="ft_sensor">
      <updateRate>100.0</updateRate>
      <topicName>force_torque</topicName>
      <jointName>FT_sensor_joint</jointName>
    </plugin>
  </gazebo>
  <!-- END OF DEFINITION FT SENSOR ============================-->
  <!-- 2 red bars 90 degrees to each other -->
  <joint name="dummyrootjoint" type="revolute">
    <parent link="dummyroot"/>
    <origin rpy="0 0 -0.7853981633974483" xyz="0 0 0"/>
    <child link="bar0"/>
    <limit effort="1000" lower="0" upper="0" velocity="10"/>
  </joint>
  <link name="bar0">
    <collision>
      <origin rpy="0 0 0" xyz="0 0 0"/>
      <geometry>
        <box size="0.4 0.01 0.01"/>
      </geometry>
    </collision>
    <visual>
      <origin rpy="0 0 0" xyz="0 0 0"/>
      <geometry>
        <box size="0.4 0.01 0.01"/>
      </geometry>
      <material name="Red"/>
    </visual>
    <inertial>
      <origin rpy="0 0 0" xyz="0 0 0"/>
      <mass value="0.1"/>
      <inertia ixx="1.6666666666666667e-06" ixy="0.0" ixz="0.0" iyy="0.0013341666666666669" iyz="0.0" izz="0.0013341666666666669"/>
    </inertial>
  </link>
  <gazebo reference="bar0">
    <material>Gazebo/Red</material>
    <mu1>0.2</mu1>
    <mu2>0.2</mu2>
  </gazebo>
  <joint name="bar_joint" type="fixed">
    <parent link="dummyroot"/>
    <origin rpy="0 0 0.7853981633974483" xyz="0 0 0"/>
    <child link="bar1"/>
  </joint>
  <link name="bar1">
    <collision>
      <origin rpy="0 0 0" xyz="0 0 0"/>
      <geometry>
        <box size="0.4 0.01 0.01"/>
      </geometry>
    </collision>
    <visual>
      <origin rpy="0 0 0" xyz="0 0 0"/>
      <geometry>
        <box size="0.4 0.01 0.01"/>
      </geometry>
      <material name="Red"/>
    </visual>
    <inertial>
      <origin rpy="0 0 0" xyz="0 0 0"/>
      <mass value="0.1"/>
      <inertia ixx="1.6666666666666667e-06" ixy="0.0" ixz="0.0" iyy="0.0013341666666666669" iyz="0.0" izz="0.0013341666666666669"/>
    </inertial>
  </link>
  <gazebo reference="bar1">
    <material>Gazebo/Red</material>
    <mu1>0.2</mu1>
    <mu2>0.2</mu2>
  </gazebo>
  <!-- one motor of each type as example - please also check file:
        < rrbot_control/config/rrbot_control.yaml >
        where the motors are referenced for virtual engine controllers -->
  <joint name="bar_motor0_joint" type="fixed">
    <parent link="bar1"/>
    <origin rpy="0 0 0" xyz="0.18 0 0.02"/>
    <child link="motor0_link"/>
  </joint>
  <link name="motor0_link">
    <collision>
      <origin rpy="0 0 0" xyz="0 0 0"/>
      <geometry>
        <cylinder length="0.03" radius="0.03"/>
      </geometry>
    </collision>
    <visual>
      <origin rpy="0 0 0" xyz="0 0 0"/>
      <geometry>
        <cylinder length="0.03" radius="0.03"/>
      </geometry>
      <material name="Black"/>
    </visual>
    <inertial>
      <origin rpy="0 0 0" xyz="0 0 0"/>
      <mass value="0.05"/>
      <inertia ixx="1.4999999999999999e-05" ixy="0.0" ixz="0.0" iyy="1.4999999999999999e-05" iyz="0.0" izz="2.25e-05"/>
    </inertial>
  </link>
  <gazebo reference="motor0_link">
    <material>Gazebo/Black</material>
    <mu1>0.2</mu1>
    <mu2>0.2</mu2>
  </gazebo>
  <!--xacro:insert_block name="gaz_extra" /-->
  <joint name="motor0" type="continuous">
    <limit effort="100" velocity="1000"/>
    <dynamics damping="0.0001" friction="0.01"/>
    <parent link="motor0_link"/>
    <origin rpy="3.141592653589793 0 0" xyz="0 0 0.025"/>
    <!-- note: rotated 180 deg to force reverse rotation -->
    <axis xyz="0 0 1"/>
    <child link="motor0_axle"/>
  </joint>
  <transmission name="motor0_trans">
    <type>transmission_interface/SimpleTransmission</type>
    <joint name="motor0">
      <hardwareInterface>hardware_interface/EffortJointInterface</hardwareInterface>
    </joint>
    <actuator name="motor0">
      <hardwareInterface>hardware_interface/EffortJointInterface</hardwareInterface>
      <mechanicalReduction>1</mechanicalReduction>
    </actuator>
  </transmission>
  <link name="motor0_axle">
    <collision>
      <origin rpy="0 0 0" xyz="0 0 0"/>
      <geometry>
        <cylinder length="0.019" radius="0.003"/>
      </geometry>
    </collision>
    <visual>
      <origin rpy="0 0 0" xyz="0 0 0"/>
      <geometry>
        <cylinder length="0.019" radius="0.003"/>
      </geometry>
      <material name="Orange"/>
    </visual>
    <inertial>
      <origin rpy="0 0 0" xyz="0 0 0"/>
      <mass value="0.05"/>
      <inertia ixx="1.6166666666666667e-06" ixy="0.0" ixz="0.0" iyy="1.6166666666666667e-06" iyz="0.0" izz="2.2500000000000002e-07"/>
    </inertial>
  </link>
  <gazebo reference="motor0_axle">
    <material>Gazebo/Orange</material>
    <mu1>0.2</mu1>
    <mu2>0.2</mu2>
  </gazebo>
  <!--xacro:insert_block name="gaz_extra" /-->
  <joint name="motor0_blade1_joint" type="revolute">
    <!-- this must be a revolute joint due to a simulator bug. it does not actually move -->
    <limit effort="1000" lower="0" upper="0" velocity="0"/>
    <parent link="motor0_axle"/>
    <origin rpy="-0.17453292519943295 0 0" xyz="0.05 0 0"/>
    <!-- this is the angle of attack of the prop blade: reverse 10 deg-->
    <axis xyz="0 0 1"/>
    <child link="motor0_blade1"/>
  </joint>
  <link name="motor0_blade1">
    <collision>
      <origin rpy="0 0 0" xyz="0 0 0"/>
      <geometry>
        <box size="0.1 0.015 0.001"/>
      </geometry>
    </collision>
    <visual>
      <origin rpy="0 0 0" xyz="0 0 0"/>
      <geometry>
        <box size="0.1 0.015 0.001"/>
      </geometry>
      <material name="Green"/>
    </visual>
    <inertial>
      <origin rpy="0 0 0" xyz="0 0 0"/>
      <mass value="0.005"/>
      <inertia ixx="9.416666666666667e-08" ixy="0.0" ixz="0.0" iyy="4.1670833333333344e-06" iyz="0.0" izz="4.2604166666666675e-06"/>
    </inertial>
  </link>
  <gazebo reference="motor0_blade1">
    <material>Gazebo/Green</material>
    <mu1>0.2</mu1>
    <mu2>0.2</mu2>
  </gazebo>
  <gazebo>
    <plugin filename="libLiftDragPlugin.so" name="motor0_blade1_lifting_surface">
      <a0>0</a0>
      <alpha_stall>0.3368</alpha_stall>
      <cla>5.418</cla>
      <cla_stall>-2.1419</cla_stall>
      <cda>0.6366197723675814</cda>
      <cda_stall>0.6366197723675814</cda_stall>
      <area>0.015</area>
      <!-- using 10 times the area to enforce lower prop speeds due to simulator limitations -->
      <air_density>1.2041</air_density>
      <forward>0 1 0</forward>
      <upward>0 0 1</upward>
      <cp>0 0 0</cp>
      <link_name>motor0_blade1</link_name>
      <radial_symmetry>false</radial_symmetry>
    </plugin>
  </gazebo>
  <joint name="motor0_blade2_joint" type="revolute">
    <!-- this must be a revolute joint due to a simulator bug. it does not actually move -->
    <limit effort="1000" lower="0" upper="0" velocity="0"/>
    <parent link="motor0_axle"/>
    <origin rpy="-0.17453292519943295 0 3.141592653589793" xyz="-0.05 0 0"/>
    <!-- this is the angle of attack of the prop blade: reverse 10 deg-->
    <axis xyz="0 0 1"/>
    <child link="motor0_blade2"/>
  </joint>
  <link name="motor0_blade2">
    <collision>
      <origin rpy="0 0 0" xyz="0 0 0"/>
      <geometry>
        <box size="0.1 0.015 0.001"/>
      </geometry>
    </collision>
    <visual>
      <origin rpy="0 0 0" xyz="0 0 0"/>
      <geometry>
        <box size="0.1 0.015 0.001"/>
      </geometry>
      <material name="Green"/>
    </visual>
    <inertial>
      <origin rpy="0 0 0" xyz="0 0 0"/>
      <mass value="0.005"/>
      <inertia ixx="9.416666666666667e-08" ixy="0.0" ixz="0.0" iyy="4.1670833333333344e-06" iyz="0.0" izz="4.2604166666666675e-06"/>
    </inertial>
  </link>
  <gazebo reference="motor0_blade2">
    <material>Gazebo/Green</material>
    <mu1>0.2</mu1>
    <mu2>0.2</mu2>
  </gazebo>
  <gazebo>
    <plugin filename="libLiftDragPlugin.so" name="motor0_blade2_lifting_surface">
      <a0>0</a0>
      <alpha_stall>0.3368</alpha_stall>
      <cla>5.418</cla>
      <cla_stall>-2.1419</cla_stall>
      <cda>0.6366197723675814</cda>
      <cda_stall>0.6366197723675814</cda_stall>
      <area>0.015</area>
      <!-- using 10 times the area to enforce lower prop speeds due to simulator limitations -->
      <air_density>1.2041</air_density>
      <forward>0 1 0</forward>
      <upward>0 0 1</upward>
      <cp>0 0 0</cp>
      <link_name>motor0_blade2</link_name>
      <radial_symmetry>false</radial_symmetry>
    </plugin>
  </gazebo>
  <joint name="bar_motor2_joint" type="fixed">
    <parent link="bar1"/>
    <origin rpy="0 0 0" xyz="-0.18 0 0.02"/>
    <child link="motor2_link"/>
  </joint>
  <link name="motor2_link">
    <collision>
      <origin rpy="0 0 0" xyz="0 0 0"/>
      <geometry>
        <cylinder length="0.03" radius="0.03"/>
      </geometry>
    </collision>
    <visual>
      <origin rpy="0 0 0" xyz="0 0 0"/>
      <geometry>
        <cylinder length="0.03" radius="0.03"/>
      </geometry>
      <material name="Black"/>
    </visual>
    <inertial>
      <origin rpy="0 0 0" xyz="0 0 0"/>
      <mass value="0.05"/>
      <inertia ixx="1.4999999999999999e-05" ixy="0.0" ixz="0.0" iyy="1.4999999999999999e-05" iyz="0.0" izz="2.25e-05"/>
    </inertial>
  </link>
  <gazebo reference="motor2_link">
    <material>Gazebo/Black</material>
    <mu1>0.2</mu1>
    <mu2>0.2</mu2>
  </gazebo>
  <!--xacro:insert_block name="gaz_extra" /-->
  <joint name="motor2" type="continuous">
    <limit effort="100" velocity="1000"/>
    <dynamics damping="0.0001" friction="0.01"/>
    <parent link="motor2_link"/>
    <origin rpy="3.141592653589793 0 0" xyz="0 0 0.025"/>
    <!-- note: rotated 180 deg to force reverse rotation -->
    <axis xyz="0 0 1"/>
    <child link="motor2_axle"/>
  </joint>
  <transmission name="motor2_trans">
    <type>transmission_interface/SimpleTransmission</type>
    <joint name="motor2">
      <hardwareInterface>hardware_interface/EffortJointInterface</hardwareInterface>
    </joint>
    <actuator name="motor2">
      <hardwareInterface>hardware_interface/EffortJointInterface</hardwareInterface>
      <mechanicalReduction>1</mechanicalReduction>
    </actuator>
  </transmission>
  <link name="motor2_axle">
    <collision>
      <origin rpy="0 0 0" xyz="0 0 0"/>
      <geometry>
        <cylinder length="0.019" radius="0.003"/>
      </geometry>
    </collision>
    <visual>
      <origin rpy="0 0 0" xyz="0 0 0"/>
      <geometry>
        <cylinder length="0.019" radius="0.003"/>
      </geometry>
      <material name="Orange"/>
    </visual>
    <inertial>
      <origin rpy="0 0 0" xyz="0 0 0"/>
      <mass value="0.05"/>
      <inertia ixx="1.6166666666666667e-06" ixy="0.0" ixz="0.0" iyy="1.6166666666666667e-06" iyz="0.0" izz="2.2500000000000002e-07"/>
    </inertial>
  </link>
  <gazebo reference="motor2_axle">
    <material>Gazebo/Orange</material>
    <mu1>0.2</mu1>
    <mu2>0.2</mu2>
  </gazebo>
  <!--xacro:insert_block name="gaz_extra" /-->
  <joint name="motor2_blade1_joint" type="revolute">
    <!-- this must be a revolute joint due to a simulator bug. it does not actually move -->
    <limit effort="1000" lower="0" upper="0" velocity="0"/>
    <parent link="motor2_axle"/>
    <origin rpy="-0.17453292519943295 0 0" xyz="0.05 0 0"/>
    <!-- this is the angle of attack of the prop blade: reverse 10 deg-->
    <axis xyz="0 0 1"/>
    <child link="motor2_blade1"/>
  </joint>
  <link name="motor2_blade1">
    <collision>
      <origin rpy="0 0 0" xyz="0 0 0"/>
      <geometry>
        <box size="0.1 0.015 0.001"/>
      </geometry>
    </collision>
    <visual>
      <origin rpy="0 0 0" xyz="0 0 0"/>
      <geometry>
        <box size="0.1 0.015 0.001"/>
      </geometry>
      <material name="Green"/>
    </visual>
    <inertial>
      <origin rpy="0 0 0" xyz="0 0 0"/>
      <mass value="0.005"/>
      <inertia ixx="9.416666666666667e-08" ixy="0.0" ixz="0.0" iyy="4.1670833333333344e-06" iyz="0.0" izz="4.2604166666666675e-06"/>
    </inertial>
  </link>
  <gazebo reference="motor2_blade1">
    <material>Gazebo/Green</material>
    <mu1>0.2</mu1>
    <mu2>0.2</mu2>
  </gazebo>
  <gazebo>
    <plugin filename="libLiftDragPlugin.so" name="motor2_blade1_lifting_surface">
      <a0>0</a0>
      <alpha_stall>0.3368</alpha_stall>
      <cla>5.418</cla>
      <cla_stall>-2.1419</cla_stall>
      <cda>0.6366197723675814</cda>
      <cda_stall>0.6366197723675814</cda_stall>
      <area>0.015</area>
      <!-- using 10 times the area to enforce lower prop speeds due to simulator limitations -->
      <air_density>1.2041</air_density>
      <forward>0 1 0</forward>
      <upward>0 0 1</upward>
      <cp>0 0 0</cp>
      <link_name>motor2_blade1</link_name>
      <radial_symmetry>false</radial_symmetry>
    </plugin>
  </gazebo>
  <joint name="motor2_blade2_joint" type="revolute">
    <!-- this must be a revolute joint due to a simulator bug. it does not actually move -->
    <limit effort="1000" lower="0" upper="0" velocity="0"/>
    <parent link="motor2_axle"/>
    <origin rpy="-0.17453292519943295 0 3.141592653589793" xyz="-0.05 0 0"/>
    <!-- this is the angle of attack of the prop blade: reverse 10 deg-->
    <axis xyz="0 0 1"/>
    <child link="motor2_blade2"/>
  </joint>
  <link name="motor2_blade2">
    <collision>
      <origin rpy="0 0 0" xyz="0 0 0"/>
      <geometry>
        <box size="0.1 0.015 0.001"/>
      </geometry>
    </collision>
    <visual>
      <origin rpy="0 0 0" xyz="0 0 0"/>
      <geometry>
        <box size="0.1 0.015 0.001"/>
      </geometry>
      <material name="Green"/>
    </visual>
    <inertial>
      <origin rpy="0 0 0" xyz="0 0 0"/>
      <mass value="0.005"/>
      <inertia ixx="9.416666666666667e-08" ixy="0.0" ixz="0.0" iyy="4.1670833333333344e-06" iyz="0.0" izz="4.2604166666666675e-06"/>
    </inertial>
  </link>
  <gazebo reference="motor2_blade2">
    <material>Gazebo/Green</material>
    <mu1>0.2</mu1>
    <mu2>0.2</mu2>
  </gazebo>
  <gazebo>
    <plugin filename="libLiftDragPlugin.so" name="motor2_blade2_lifting_surface">
      <a0>0</a0>
      <alpha_stall>0.3368</alpha_stall>
      <cla>5.418</cla>
      <cla_stall>-2.1419</cla_stall>
      <cda>0.6366197723675814</cda>
      <cda_stall>0.6366197723675814</cda_stall>
      <area>0.015</area>
      <!-- using 10 times the area to enforce lower prop speeds due to simulator limitations -->
      <air_density>1.2041</air_density>
      <forward>0 1 0</forward>
      <upward>0 0 1</upward>
      <cp>0 0 0</cp>
      <link_name>motor2_blade2</link_name>
      <radial_symmetry>false</radial_symmetry>
    </plugin>
  </gazebo>
  <joint name="bar_motor1_joint" type="fixed">
    <parent link="bar0"/>
    <origin rpy="0 0 0" xyz="0.18 0 0.02"/>
    <child link="motor1_link"/>
  </joint>
  <link name="motor1_link">
    <collision>
      <origin rpy="0 0 0" xyz="0 0 0"/>
      <geometry>
        <cylinder length="0.03" radius="0.03"/>
      </geometry>
    </collision>
    <visual>
      <origin rpy="0 0 0" xyz="0 0 0"/>
      <geometry>
        <cylinder length="0.03" radius="0.03"/>
      </geometry>
      <material name="Black"/>
    </visual>
    <inertial>
      <origin rpy="0 0 0" xyz="0 0 0"/>
      <mass value="0.05"/>
      <inertia ixx="1.4999999999999999e-05" ixy="0.0" ixz="0.0" iyy="1.4999999999999999e-05" iyz="0.0" izz="2.25e-05"/>
    </inertial>
  </link>
  <gazebo reference="motor1_link">
    <material>Gazebo/Black</material>
    <mu1>0.2</mu1>
    <mu2>0.2</mu2>
  </gazebo>
  <!--xacro:insert_block name="gaz_extra" /-->
  <joint name="motor1" type="continuous">
    <limit effort="100" velocity="1000"/>
    <dynamics damping="0.0001" friction="0.01"/>
    <parent link="motor1_link"/>
    <origin rpy="0 0 0" xyz="0 0 0.025"/>
    <axis xyz="0 0 1"/>
    <child link="motor1_axle"/>
  </joint>
  <transmission name="motor1_trans">
    <type>transmission_interface/SimpleTransmission</type>
    <joint name="motor1">
      <hardwareInterface>hardware_interface/EffortJointInterface</hardwareInterface>
    </joint>
    <actuator name="motor1">
      <hardwareInterface>hardware_interface/EffortJointInterface</hardwareInterface>
      <mechanicalReduction>1</mechanicalReduction>
    </actuator>
  </transmission>
  <link name="motor1_axle">
    <collision>
      <origin rpy="0 0 0" xyz="0 0 0"/>
      <geometry>
        <cylinder length="0.019" radius="0.003"/>
      </geometry>
    </collision>
    <visual>
      <origin rpy="0 0 0" xyz="0 0 0"/>
      <geometry>
        <cylinder length="0.019" radius="0.003"/>
      </geometry>
      <material name="Orange"/>
    </visual>
    <inertial>
      <origin rpy="0 0 0" xyz="0 0 0"/>
      <mass value="0.05"/>
      <inertia ixx="1.6166666666666667e-06" ixy="0.0" ixz="0.0" iyy="1.6166666666666667e-06" iyz="0.0" izz="2.2500000000000002e-07"/>
    </inertial>
  </link>
  <gazebo reference="motor1_axle">
    <material>Gazebo/Orange</material>
    <mu1>0.2</mu1>
    <mu2>0.2</mu2>
  </gazebo>
  <!--xacro:insert_block name="gaz_extra" /-->
  <joint name="motor1_blade1_joint" type="revolute">
    <!-- this must be a revolute joint due to a simulator bug. it does not actually move -->
    <limit effort="1000" lower="0" upper="0" velocity="0"/>
    <parent link="motor1_axle"/>
    <origin rpy="0.17453292519943295 0 0" xyz="0.05 0 0"/>
    <!-- this is the angle of attack of the prop blade: 10 deg-->
    <axis xyz="0 0 1"/>
    <child link="motor1_blade1"/>
  </joint>
  <link name="motor1_blade1">
    <collision>
      <origin rpy="0 0 0" xyz="0 0 0"/>
      <geometry>
        <box size="0.1 0.015 0.001"/>
      </geometry>
    </collision>
    <visual>
      <origin rpy="0 0 0" xyz="0 0 0"/>
      <geometry>
        <box size="0.1 0.015 0.001"/>
      </geometry>
      <material name="Orange"/>
    </visual>
    <inertial>
      <origin rpy="0 0 0" xyz="0 0 0"/>
      <mass value="0.005"/>
      <inertia ixx="9.416666666666667e-08" ixy="0.0" ixz="0.0" iyy="4.1670833333333344e-06" iyz="0.0" izz="4.2604166666666675e-06"/>
    </inertial>
  </link>
  <gazebo reference="motor1_blade1">
    <material>Gazebo/Orange</material>
    <mu1>0.2</mu1>
    <mu2>0.2</mu2>
  </gazebo>
  <gazebo>
    <plugin filename="libLiftDragPlugin.so" name="motor1_blade1_lifting_surface">
      <a0>0</a0>
      <alpha_stall>0.3368</alpha_stall>
      <cla>5.418</cla>
      <cla_stall>-2.1419</cla_stall>
      <cda>0.6366197723675814</cda>
      <cda_stall>0.6366197723675814</cda_stall>
      <area>0.015</area>
      <!-- using 10 times the area to enforce lower prop speeds due to simulator limitations -->
      <air_density>1.2041</air_density>
      <forward>0 1 0</forward>
      <upward>0 0 1</upward>
      <cp>0 0 0</cp>
      <link_name>motor1_blade1</link_name>
      <radial_symmetry>false</radial_symmetry>
    </plugin>
  </gazebo>
  <joint name="motor1_blade2_joint" type="revolute">
    <!-- this must be a revolute joint due to a simulator bug. it does not actually move -->
    <limit effort="1000" lower="0" upper="0" velocity="0"/>
    <parent link="motor1_axle"/>
    <origin rpy="0.17453292519943295 0 3.141592653589793" xyz="-0.05 0 0"/>
    <!-- this is the angle of attack of the prop blade: 10 deg-->
    <axis xyz="0 0 1"/>
    <child link="motor1_blade2"/>
  </joint>
  <link name="motor1_blade2">
    <collision>
      <origin rpy="0 0 0" xyz="0 0 0"/>
      <geometry>
        <box size="0.1 0.015 0.001"/>
      </geometry>
    </collision>
    <visual>
      <origin rpy="0 0 0" xyz="0 0 0"/>
      <geometry>
        <box size="0.1 0.015 0.001"/>
      </geometry>
      <material name="Orange"/>
    </visual>
    <inertial>
      <origin rpy="0 0 0" xyz="0 0 0"/>
      <mass value="0.005"/>
      <inertia ixx="9.416666666666667e-08" ixy="0.0" ixz="0.0" iyy="4.1670833333333344e-06" iyz="0.0" izz="4.2604166666666675e-06"/>
    </inertial>
  </link>
  <gazebo reference="motor1_blade2">
    <material>Gazebo/Orange</material>
    <mu1>0.2</mu1>
    <mu2>0.2</mu2>
  </gazebo>
  <gazebo>
    <plugin filename="libLiftDragPlugin.so" name="motor1_blade2_lifting_surface">
      <a0>0</a0>
      <alpha_stall>0.3368</alpha_stall>
      <cla>5.418</cla>
      <cla_stall>-2.1419</cla_stall>
      <cda>0.6366197723675814</cda>
      <cda_stall>0.6366197723675814</cda_stall>
      <area>0.015</area>
      <!-- using 10 times the area to enforce lower prop speeds due to simulator limitations -->
      <air_density>1.2041</air_density>
      <forward>0 1 0</forward>
      <upward>0 0 1</upward>
      <cp>0 0 0</cp>
      <link_name>motor1_blade2</link_name>
      <radial_symmetry>false</radial_symmetry>
    </plugin>
  </gazebo>
  <joint name="bar_motor3_joint" type="fixed">
    <parent link="bar0"/>
    <origin rpy="0 0 0" xyz="-0.18 0 0.02"/>
    <child link="motor3_link"/>
  </joint>
  <link name="motor3_link">
    <collision>
      <origin rpy="0 0 0" xyz="0 0 0"/>
      <geometry>
        <cylinder length="0.03" radius="0.03"/>
      </geometry>
    </collision>
    <visual>
      <origin rpy="0 0 0" xyz="0 0 0"/>
      <geometry>
        <cylinder length="0.03" radius="0.03"/>
      </geometry>
      <material name="Black"/>
    </visual>
    <inertial>
      <origin rpy="0 0 0" xyz="0 0 0"/>
      <mass value="0.05"/>
      <inertia ixx="1.4999999999999999e-05" ixy="0.0" ixz="0.0" iyy="1.4999999999999999e-05" iyz="0.0" izz="2.25e-05"/>
    </inertial>
  </link>
  <gazebo reference="motor3_link">
    <material>Gazebo/Black</material>
    <mu1>0.2</mu1>
    <mu2>0.2</mu2>
  </gazebo>
  <!--xacro:insert_block name="gaz_extra" /-->
  <joint name="motor3" type="continuous">
    <limit effort="100" velocity="1000"/>
    <dynamics damping="0.0001" friction="0.01"/>
    <parent link="motor3_link"/>
    <origin rpy="0 0 0" xyz="0 0 0.025"/>
    <axis xyz="0 0 1"/>
    <child link="motor3_axle"/>
  </joint>
  <transmission name="motor3_trans">
    <type>transmission_interface/SimpleTransmission</type>
    <joint name="motor3">
      <hardwareInterface>hardware_interface/EffortJointInterface</hardwareInterface>
    </joint>
    <actuator name="motor3">
      <hardwareInterface>hardware_interface/EffortJointInterface</hardwareInterface>
      <mechanicalReduction>1</mechanicalReduction>
    </actuator>
  </transmission>
  <link name="motor3_axle">
    <collision>
      <origin rpy="0 0 0" xyz="0 0 0"/>
      <geometry>
        <cylinder length="0.019" radius="0.003"/>
      </geometry>
    </collision>
    <visual>
      <origin rpy="0 0 0" xyz="0 0 0"/>
      <geometry>
        <cylinder length="0.019" radius="0.003"/>
      </geometry>
      <material name="Orange"/>
    </visual>
    <inertial>
      <origin rpy="0 0 0" xyz="0 0 0"/>
      <mass value="0.05"/>
      <inertia ixx="1.6166666666666667e-06" ixy="0.0" ixz="0.0" iyy="1.6166666666666667e-06" iyz="0.0" izz="2.2500000000000002e-07"/>
    </inertial>
  </link>
  <gazebo reference="motor3_axle">
    <material>Gazebo/Orange</material>
    <mu1>0.2</mu1>
    <mu2>0.2</mu2>
  </gazebo>
  <!--xacro:insert_block name="gaz_extra" /-->
  <joint name="motor3_blade1_joint" type="revolute">
    <!-- this must be a revolute joint due to a simulator bug. it does not actually move -->
    <limit effort="1000" lower="0" upper="0" velocity="0"/>
    <parent link="motor3_axle"/>
    <origin rpy="0.17453292519943295 0 0" xyz="0.05 0 0"/>
    <!-- this is the angle of attack of the prop blade: 10 deg-->
    <axis xyz="0 0 1"/>
    <child link="motor3_blade1"/>
  </joint>
  <link name="motor3_blade1">
    <collision>
      <origin rpy="0 0 0" xyz="0 0 0"/>
      <geometry>
        <box size="0.1 0.015 0.001"/>
      </geometry>
    </collision>
    <visual>
      <origin rpy="0 0 0" xyz="0 0 0"/>
      <geometry>
        <box size="0.1 0.015 0.001"/>
      </geometry>
      <material name="Orange"/>
    </visual>
    <inertial>
      <origin rpy="0 0 0" xyz="0 0 0"/>
      <mass value="0.005"/>
      <inertia ixx="9.416666666666667e-08" ixy="0.0" ixz="0.0" iyy="4.1670833333333344e-06" iyz="0.0" izz="4.2604166666666675e-06"/>
    </inertial>
  </link>
  <gazebo reference="motor3_blade1">
    <material>Gazebo/Orange</material>
    <mu1>0.2</mu1>
    <mu2>0.2</mu2>
  </gazebo>
  <gazebo>
    <plugin filename="libLiftDragPlugin.so" name="motor3_blade1_lifting_surface">
      <a0>0</a0>
      <alpha_stall>0.3368</alpha_stall>
      <cla>5.418</cla>
      <cla_stall>-2.1419</cla_stall>
      <cda>0.6366197723675814</cda>
      <cda_stall>0.6366197723675814</cda_stall>
      <area>0.015</area>
      <!-- using 10 times the area to enforce lower prop speeds due to simulator limitations -->
      <air_density>1.2041</air_density>
      <forward>0 1 0</forward>
      <upward>0 0 1</upward>
      <cp>0 0 0</cp>
      <link_name>motor3_blade1</link_name>
      <radial_symmetry>false</radial_symmetry>
    </plugin>
  </gazebo>
  <joint name="motor3_blade2_joint" type="revolute">
    <!-- this must be a revolute joint due to a simulator bug. it does not actually move -->
    <limit effort="1000" lower="0" upper="0" velocity="0"/>
    <parent link="motor3_axle"/>
    <origin rpy="0.17453292519943295 0 3.141592653589793" xyz="-0.05 0 0"/>
    <!-- this is the angle of attack of the prop blade: 10 deg-->
    <axis xyz="0 0 1"/>
    <child link="motor3_blade2"/>
  </joint>
  <link name="motor3_blade2">
    <collision>
      <origin rpy="0 0 0" xyz="0 0 0"/>
      <geometry>
        <box size="0.1 0.015 0.001"/>
      </geometry>
    </collision>
    <visual>
      <origin rpy="0 0 0" xyz="0 0 0"/>
      <geometry>
        <box size="0.1 0.015 0.001"/>
      </geometry>
      <material name="Orange"/>
    </visual>
    <inertial>
      <origin rpy="0 0 0" xyz="0 0 0"/>
      <mass value="0.005"/>
      <inertia ixx="9.416666666666667e-08" ixy="0.0" ixz="0.0" iyy="4.1670833333333344e-06" iyz="0.0" izz="4.2604166666666675e-06"/>
    </inertial>
  </link>
  <gazebo reference="motor3_blade2">
    <material>Gazebo/Orange</material>
    <mu1>0.2</mu1>
    <mu2>0.2</mu2>
  </gazebo>
  <gazebo>
    <plugin filename="libLiftDragPlugin.so" name="motor3_blade2_lifting_surface">
      <a0>0</a0>
      <alpha_stall>0.3368</alpha_stall>
      <cla>5.418</cla>
      <cla_stall>-2.1419</cla_stall>
      <cda>0.6366197723675814</cda>
      <cda_stall>0.6366197723675814</cda_stall>
      <area>0.015</area>
      <!-- using 10 times the area to enforce lower prop speeds due to simulator limitations -->
      <air_density>1.2041</air_density>
      <forward>0 1 0</forward>
      <upward>0 0 1</upward>
      <cp>0 0 0</cp>
      <link_name>motor3_blade2</link_name>
      <radial_symmetry>false</radial_symmetry>
    </plugin>
  </gazebo>
  <!-- BEGIN force/torque sensor -->
  <!-- <xacro:fixed_joint_force_torque_macro name_joint="force_torque_sensor_joint" parent="dummyroot" child="force_torque_sensor" /> -->
  <!-- END force/torque sensor -->
</robot>

